<?xml version="1.0"?>
<robot name="simple_humanoid">
  <!-- Base/Fixed link -->
  <link name="base_link">
    <visual>
      <geometry>
        <box size="0.3 0.2 0.1"/>
      </geometry>
      <material name="gray">
        <color rgba="0.5 0.5 0.5 1.0"/>
      </material>
    </visual>
    <collision>
      <geometry>
        <box size="0.3 0.2 0.1"/>
      </geometry>
    </collision>
    <inertial>
      <mass value="5.0"/>
      <inertia ixx="0.1" ixy="0.0" ixz="0.0" iyy="0.1" iyz="0.0" izz="0.1"/>
    </inertial>
  </link>

  <!-- Torso -->
  <link name="torso">
    <visual>
      <geometry>
        <box size="0.2 0.15 0.5"/>
      </geometry>
      <material name="blue">
        <color rgba="0.2 0.2 0.8 1.0"/>
      </material>
    </visual>
    <collision>
      <geometry>
        <box size="0.2 0.15 0.5"/>
      </geometry>
    </collision>
    <inertial>
      <mass value="3.0"/>
      <inertia ixx="0.1" ixy="0.0" ixz="0.0" iyy="0.1" iyz="0.0" izz="0.1"/>
    </inertial>
  </link>

  <joint name="torso_joint" type="fixed">
    <parent link="base_link"/>
    <child link="torso"/>
    <origin xyz="0 0 0.3" rpy="0 0 0"/>
  </joint>

  <!-- Head -->
  <link name="head">
    <visual>
      <geometry>
        <sphere radius="0.1"/>
      </geometry>
      <material name="skin">
        <color rgba="1.0 0.8 0.6 1.0"/>
      </material>
    </visual>
    <collision>
      <geometry>
        <sphere radius="0.1"/>
      </geometry>
    </collision>
    <inertial>
      <mass value="1.0"/>
      <inertia ixx="0.01" ixy="0.0" ixz="0.0" iyy="0.01" iyz="0.0" izz="0.01"/>
    </inertial>
  </link>

  <joint name="neck_joint" type="revolute">
    <parent link="torso"/>
    <child link="head"/>
    <origin xyz="0 0 0.3" rpy="0 0 0"/>
    <axis xyz="0 1 0"/>
    <limit lower="-0.5" upper="0.5" effort="10" velocity="2"/>
  </joint>

  <!-- Left Arm -->
  <link name="left_upper_arm">
    <visual>
      <geometry>
        <cylinder radius="0.05" length="0.3"/>
      </geometry>
      <material name="red">
        <color rgba="0.8 0.2 0.2 1.0"/>
      </material>
    </visual>
    <collision>
      <geometry>
        <cylinder radius="0.05" length="0.3"/>
      </geometry>
    </collision>
    <inertial>
      <mass value="0.8"/>
      <inertia ixx="0.01" ixy="0.0" ixz="0.0" iyy="0.01" iyz="0.0" izz="0.001"/>
    </inertial>
  </link>

  <joint name="left_shoulder_pitch" type="revolute">
    <parent link="torso"/>
    <child link="left_upper_arm"/>
    <origin xyz="0.15 0.1 0.1" rpy="0 0 0"/>
    <axis xyz="0 1 0"/>
    <limit lower="-1.57" upper="1.57" effort="50" velocity="2"/>
  </joint>

  <link name="left_lower_arm">
    <visual>
      <geometry>
        <cylinder radius="0.04" length="0.25"/>
      </geometry>
      <material name="red">
        <color rgba="0.8 0.2 0.2 1.0"/>
      </material>
    </visual>
    <collision>
      <geometry>
        <cylinder radius="0.04" length="0.25"/>
      </geometry>
    </collision>
    <inertial>
      <mass value="0.5"/>
      <inertia ixx="0.008" ixy="0.0" ixz="0.0" iyy="0.008" iyz="0.0" izz="0.001"/>
    </inertial>
  </link>

  <joint name="left_elbow" type="revolute">
    <parent link="left_upper_arm"/>
    <child link="left_lower_arm"/>
    <origin xyz="0 0 -0.3" rpy="0 0 0"/>
    <axis xyz="0 1 0"/>
    <limit lower="0" upper="2.35" effort="40" velocity="2"/>
  </joint>

  <!-- Right Arm (symmetric) -->
  <link name="right_upper_arm">
    <visual>
      <geometry>
        <cylinder radius="0.05" length="0.3"/>
      </geometry>
      <material name="red">
        <color rgba="0.8 0.2 0.2 1.0"/>
      </material>
    </visual>
    <collision>
      <geometry>
        <cylinder radius="0.05" length="0.3"/>
      </geometry>
    </collision>
    <inertial>
      <mass value="0.8"/>
      <inertia ixx="0.01" ixy="0.0" ixz="0.0" iyy="0.01" iyz="0.0" izz="0.001"/>
    </inertial>
  </link>

  <joint name="right_shoulder_pitch" type="revolute">
    <parent link="torso"/>
    <child link="right_upper_arm"/>
    <origin xyz="0.15 -0.1 0.1" rpy="0 0 0"/>
    <axis xyz="0 1 0"/>
    <limit lower="-1.57" upper="1.57" effort="50" velocity="2"/>
  </joint>

  <link name="right_lower_arm">
    <visual>
      <geometry>
        <cylinder radius="0.04" length="0.25"/>
      </geometry>
      <material name="red">
        <color rgba="0.8 0.2 0.2 1.0"/>
      </material>
    </visual>
    <collision>
      <geometry>
        <cylinder radius="0.04" length="0.25"/>
      </geometry>
    </collision>
    <inertial>
      <mass value="0.5"/>
      <inertia ixx="0.008" ixy="0.0" ixz="0.0" iyy="0.008" iyz="0.0" izz="0.001"/>
    </inertial>
  </link>

  <joint name="right_elbow" type="revolute">
    <parent link="right_upper_arm"/>
    <child link="right_lower_arm"/>
    <origin xyz="0 0 -0.3" rpy="0 0 0"/>
    <axis xyz="0 1 0"/>
    <limit lower="0" upper="2.35" effort="40" velocity="2"/>
  </joint>

  <!-- Left Leg -->
  <link name="left_thigh">
    <visual>
      <geometry>
        <cylinder radius="0.06" length="0.4"/>
      </geometry>
      <material name="green">
        <color rgba="0.2 0.8 0.2 1.0"/>
      </material>
    </visual>
    <collision>
      <geometry>
        <cylinder radius="0.06" length="0.4"/>
      </geometry>
    </collision>
    <inertial>
      <mass value="1.2"/>
      <inertia ixx="0.02" ixy="0.0" ixz="0.0" iyy="0.02" iyz="0.0" izz="0.002"/>
    </inertial>
  </link>

  <joint name="left_hip_pitch" type="revolute">
    <parent link="torso"/>
    <child link="left_thigh"/>
    <origin xyz="-0.1 0.05 -0.25" rpy="0 0 0"/>
    <axis xyz="0 1 0"/>
    <limit lower="-0.78" upper="0.78" effort="100" velocity="2"/>
  </joint>

  <link name="left_shin">
    <visual>
      <geometry>
        <cylinder radius="0.05" length="0.4"/>
      </geometry>
      <material name="green">
        <color rgba="0.2 0.8 0.2 1.0"/>
      </material>
    </visual>
    <collision>
      <geometry>
        <cylinder radius="0.05" length="0.4"/>
      </geometry>
    </collision>
    <inertial>
      <mass value="0.8"/>
      <inertia ixx="0.015" ixy="0.0" ixz="0.0" iyy="0.015" iyz="0.0" izz="0.0015"/>
    </inertial>
  </link>

  <joint name="left_knee" type="revolute">
    <parent link="left_thigh"/>
    <child link="left_shin"/>
    <origin xyz="0 0 -0.4" rpy="0 0 0"/>
    <axis xyz="0 1 0"/>
    <limit lower="0" upper="2.35" effort="80" velocity="2"/>
  </joint>

  <link name="left_foot">
    <visual>
      <geometry>
        <box size="0.15 0.1 0.05"/>
      </geometry>
      <material name="black">
        <color rgba="0.1 0.1 0.1 1.0"/>
      </material>
    </visual>
    <collision>
      <geometry>
        <box size="0.15 0.1 0.05"/>
      </geometry>
    </collision>
    <inertial>
      <mass value="0.3"/>
      <inertia ixx="0.001" ixy="0.0" ixz="0.0" iyy="0.001" iyz="0.0" izz="0.001"/>
    </inertial>
  </link>

  <joint name="left_ankle" type="revolute">
    <parent link="left_shin"/>
    <child link="left_foot"/>
    <origin xyz="0 0 -0.4" rpy="0 0 0"/>
    <axis xyz="0 1 0"/>
    <limit lower="-0.52" upper="0.52" effort="50" velocity="2"/>
  </joint>

  <!-- Right Leg (symmetric) -->
  <link name="right_thigh">
    <visual>
      <geometry>
        <cylinder radius="0.06" length="0.4"/>
      </geometry>
      <material name="green">
        <color rgba="0.2 0.8 0.2 1.0"/>
      </material>
    </visual>
    <collision>
      <geometry>
        <cylinder radius="0.06" length="0.4"/>
      </geometry>
    </collision>
    <inertial>
      <mass value="1.2"/>
      <inertia ixx="0.02" ixy="0.0" ixz="0.0" iyy="0.02" iyz="0.0" izz="0.002"/>
    </inertial>
  </link>

  <joint name="right_hip_pitch" type="revolute">
    <parent link="torso"/>
    <child link="right_thigh"/>
    <origin xyz="-0.1 -0.05 -0.25" rpy="0 0 0"/>
    <axis xyz="0 1 0"/>
    <limit lower="-0.78" upper="0.78" effort="100" velocity="2"/>
  </joint>

  <link name="right_shin">
    <visual>
      <geometry>
        <cylinder radius="0.05" length="0.4"/>
      </geometry>
      <material name="green">
        <color rgba="0.2 0.8 0.2 1.0"/>
      </material>
    </visual>
    <collision>
      <geometry>
        <cylinder radius="0.05" length="0.4"/>
      </geometry>
    </collision>
    <inertial>
      <mass value="0.8"/>
      <inertia ixx="0.015" ixy="0.0" ixz="0.0" iyy="0.015" iyz="0.0" izz="0.0015"/>
    </inertial>
  </link>

  <joint name="right_knee" type="revolute">
    <parent link="right_thigh"/>
    <child link="right_shin"/>
    <origin xyz="0 0 -0.4" rpy="0 0 0"/>
    <axis xyz="0 1 0"/>
    <limit lower="0" upper="2.35" effort="80" velocity="2"/>
  </joint>

  <link name="right_foot">
    <visual>
      <geometry>
        <box size="0.15 0.1 0.05"/>
      </geometry>
      <material name="black">
        <color rgba="0.1 0.1 0.1 1.0"/>
      </material>
    </visual>
    <collision>
      <geometry>
        <box size="0.15 0.1 0.05"/>
      </geometry>
    </collision>
    <inertial>
      <mass value="0.3"/>
      <inertia ixx="0.001" ixy="0.0" ixz="0.0" iyy="0.001" iyz="0.0" izz="0.001"/>
    </inertial>
  </link>

  <joint name="right_ankle" type="revolute">
    <parent link="right_shin"/>
    <child link="right_foot"/>
    <origin xyz="0 0 -0.4" rpy="0 0 0"/>
    <axis xyz="0 1 0"/>
    <limit lower="-0.52" upper="0.52" effort="50" velocity="2"/>
  </joint>
</robot>